2020-04-28 17:55:39,206 ERROR: Exception on /index [GET] [in /home/toasterkief/PyLibrary/Web/Flask/symphonyIO/venv/lib/python3.8/site-packages/flask/app.py:1891]
Traceback (most recent call last):
  File "/home/toasterkief/PyLibrary/Web/Flask/symphonyIO/venv/lib/python3.8/site-packages/flask/app.py", line 2447, in wsgi_app
    response = self.full_dispatch_request()
  File "/home/toasterkief/PyLibrary/Web/Flask/symphonyIO/venv/lib/python3.8/site-packages/flask/app.py", line 1952, in full_dispatch_request
    rv = self.handle_user_exception(e)
  File "/home/toasterkief/PyLibrary/Web/Flask/symphonyIO/venv/lib/python3.8/site-packages/flask/app.py", line 1821, in handle_user_exception
    reraise(exc_type, exc_value, tb)
  File "/home/toasterkief/PyLibrary/Web/Flask/symphonyIO/venv/lib/python3.8/site-packages/flask/_compat.py", line 39, in reraise
    raise value
  File "/home/toasterkief/PyLibrary/Web/Flask/symphonyIO/venv/lib/python3.8/site-packages/flask/app.py", line 1950, in full_dispatch_request
    rv = self.dispatch_request()
  File "/home/toasterkief/PyLibrary/Web/Flask/symphonyIO/venv/lib/python3.8/site-packages/flask/app.py", line 1936, in dispatch_request
    return self.view_functions[rule.endpoint](**req.view_args)
  File "/home/toasterkief/PyLibrary/Web/Flask/symphonyIO/venv/lib/python3.8/site-packages/flask_login/utils.py", line 272, in decorated_view
    return func(*args, **kwargs)
  File "/home/toasterkief/PyLibrary/Web/Flask/symphonyIO/app/routes.py", line 42, in index
    return render_template('index.html', title='Home Chamber', form=form, posts=posts.items, next_url=next_url, prev_url=prev_url)
  File "/home/toasterkief/PyLibrary/Web/Flask/symphonyIO/venv/lib/python3.8/site-packages/flask/templating.py", line 137, in render_template
    return _render(
  File "/home/toasterkief/PyLibrary/Web/Flask/symphonyIO/venv/lib/python3.8/site-packages/flask/templating.py", line 120, in _render
    rv = template.render(context)
  File "/home/toasterkief/PyLibrary/Web/Flask/symphonyIO/venv/lib/python3.8/site-packages/jinja2/environment.py", line 1090, in render
    self.environment.handle_exception()
  File "/home/toasterkief/PyLibrary/Web/Flask/symphonyIO/venv/lib/python3.8/site-packages/jinja2/environment.py", line 832, in handle_exception
    reraise(*rewrite_traceback_stack(source=source))
  File "/home/toasterkief/PyLibrary/Web/Flask/symphonyIO/venv/lib/python3.8/site-packages/jinja2/_compat.py", line 28, in reraise
    raise value.with_traceback(tb)
  File "/home/toasterkief/PyLibrary/Web/Flask/symphonyIO/app/templates/index.html", line 2, in top-level template code
    {% import 'bootstrap/wtf.html' as wtf %}
  File "/home/toasterkief/PyLibrary/Web/Flask/symphonyIO/app/templates/base.html", line 1, in top-level template code
    {% extends 'bootstrap/base.html' %}
  File "/home/toasterkief/PyLibrary/Web/Flask/symphonyIO/venv/lib/python3.8/site-packages/flask_bootstrap/templates/bootstrap/base.html", line 1, in top-level template code
    {% block doc -%}
  File "/home/toasterkief/PyLibrary/Web/Flask/symphonyIO/venv/lib/python3.8/site-packages/flask_bootstrap/templates/bootstrap/base.html", line 4, in block "doc"
    {%- block html %}
  File "/home/toasterkief/PyLibrary/Web/Flask/symphonyIO/venv/lib/python3.8/site-packages/flask_bootstrap/templates/bootstrap/base.html", line 20, in block "html"
    {% block body -%}
  File "/home/toasterkief/PyLibrary/Web/Flask/symphonyIO/venv/lib/python3.8/site-packages/flask_bootstrap/templates/bootstrap/base.html", line 21, in block "body"
    {% block navbar %}
  File "/home/toasterkief/PyLibrary/Web/Flask/symphonyIO/app/templates/base.html", line 33, in block "navbar"
    <li><a href="{{ url_for('tracks', username=current_user.username) }}">My Tracks</a></li>
  File "/home/toasterkief/PyLibrary/Web/Flask/symphonyIO/venv/lib/python3.8/site-packages/flask/helpers.py", line 370, in url_for
    return appctx.app.handle_url_build_error(error, endpoint, values)
  File "/home/toasterkief/PyLibrary/Web/Flask/symphonyIO/venv/lib/python3.8/site-packages/flask/app.py", line 2216, in handle_url_build_error
    reraise(exc_type, exc_value, tb)
  File "/home/toasterkief/PyLibrary/Web/Flask/symphonyIO/venv/lib/python3.8/site-packages/flask/_compat.py", line 39, in reraise
    raise value
  File "/home/toasterkief/PyLibrary/Web/Flask/symphonyIO/venv/lib/python3.8/site-packages/flask/helpers.py", line 357, in url_for
    rv = url_adapter.build(
  File "/home/toasterkief/PyLibrary/Web/Flask/symphonyIO/venv/lib/python3.8/site-packages/werkzeug/routing.py", line 2179, in build
    raise BuildError(endpoint, values, method, self)
werkzeug.routing.BuildError: Could not build url for endpoint 'tracks' with values ['username']. Did you mean 'bootstrap.static' instead?
2020-04-28 17:56:16,904 INFO: Symphony IO Site Started Up [in /home/toasterkief/PyLibrary/Web/Flask/symphonyIO/app/__init__.py:59]
2020-04-28 17:56:41,069 ERROR: Exception on /upload [GET] [in /home/toasterkief/PyLibrary/Web/Flask/symphonyIO/venv/lib/python3.8/site-packages/flask/app.py:1891]
Traceback (most recent call last):
  File "/home/toasterkief/PyLibrary/Web/Flask/symphonyIO/venv/lib/python3.8/site-packages/flask/app.py", line 2447, in wsgi_app
    response = self.full_dispatch_request()
  File "/home/toasterkief/PyLibrary/Web/Flask/symphonyIO/venv/lib/python3.8/site-packages/flask/app.py", line 1952, in full_dispatch_request
    rv = self.handle_user_exception(e)
  File "/home/toasterkief/PyLibrary/Web/Flask/symphonyIO/venv/lib/python3.8/site-packages/flask/app.py", line 1821, in handle_user_exception
    reraise(exc_type, exc_value, tb)
  File "/home/toasterkief/PyLibrary/Web/Flask/symphonyIO/venv/lib/python3.8/site-packages/flask/_compat.py", line 39, in reraise
    raise value
  File "/home/toasterkief/PyLibrary/Web/Flask/symphonyIO/venv/lib/python3.8/site-packages/flask/app.py", line 1950, in full_dispatch_request
    rv = self.dispatch_request()
  File "/home/toasterkief/PyLibrary/Web/Flask/symphonyIO/venv/lib/python3.8/site-packages/flask/app.py", line 1936, in dispatch_request
    return self.view_functions[rule.endpoint](**req.view_args)
  File "/home/toasterkief/PyLibrary/Web/Flask/symphonyIO/venv/lib/python3.8/site-packages/flask_login/utils.py", line 272, in decorated_view
    return func(*args, **kwargs)
  File "/home/toasterkief/PyLibrary/Web/Flask/symphonyIO/app/routes.py", line 207, in upload
    return render_template('upload.html', title='Upload Music', form=form)
  File "/home/toasterkief/PyLibrary/Web/Flask/symphonyIO/venv/lib/python3.8/site-packages/flask/templating.py", line 138, in render_template
    ctx.app.jinja_env.get_or_select_template(template_name_or_list),
  File "/home/toasterkief/PyLibrary/Web/Flask/symphonyIO/venv/lib/python3.8/site-packages/jinja2/environment.py", line 930, in get_or_select_template
    return self.get_template(template_name_or_list, parent, globals)
  File "/home/toasterkief/PyLibrary/Web/Flask/symphonyIO/venv/lib/python3.8/site-packages/jinja2/environment.py", line 883, in get_template
    return self._load_template(name, self.make_globals(globals))
  File "/home/toasterkief/PyLibrary/Web/Flask/symphonyIO/venv/lib/python3.8/site-packages/jinja2/environment.py", line 857, in _load_template
    template = self.loader.load(self, name, globals)
  File "/home/toasterkief/PyLibrary/Web/Flask/symphonyIO/venv/lib/python3.8/site-packages/jinja2/loaders.py", line 115, in load
    source, filename, uptodate = self.get_source(environment, name)
  File "/home/toasterkief/PyLibrary/Web/Flask/symphonyIO/venv/lib/python3.8/site-packages/flask/templating.py", line 60, in get_source
    return self._get_source_fast(environment, template)
  File "/home/toasterkief/PyLibrary/Web/Flask/symphonyIO/venv/lib/python3.8/site-packages/flask/templating.py", line 89, in _get_source_fast
    raise TemplateNotFound(template)
jinja2.exceptions.TemplateNotFound: upload.html
2020-04-28 17:58:30,100 INFO: Symphony IO Site Started Up [in /home/toasterkief/PyLibrary/Web/Flask/symphonyIO/app/__init__.py:59]
2020-04-28 18:04:44,853 INFO: Symphony IO Site Started Up [in /home/toasterkief/PyLibrary/Web/Flask/symphonyIO/app/__init__.py:59]
2020-04-28 18:05:29,849 ERROR: Exception on /upload [POST] [in /home/toasterkief/PyLibrary/Web/Flask/symphonyIO/venv/lib/python3.8/site-packages/flask/app.py:1891]
Traceback (most recent call last):
  File "/home/toasterkief/PyLibrary/Web/Flask/symphonyIO/venv/lib/python3.8/site-packages/flask/app.py", line 2447, in wsgi_app
    response = self.full_dispatch_request()
  File "/home/toasterkief/PyLibrary/Web/Flask/symphonyIO/venv/lib/python3.8/site-packages/flask/app.py", line 1952, in full_dispatch_request
    rv = self.handle_user_exception(e)
  File "/home/toasterkief/PyLibrary/Web/Flask/symphonyIO/venv/lib/python3.8/site-packages/flask/app.py", line 1821, in handle_user_exception
    reraise(exc_type, exc_value, tb)
  File "/home/toasterkief/PyLibrary/Web/Flask/symphonyIO/venv/lib/python3.8/site-packages/flask/_compat.py", line 39, in reraise
    raise value
  File "/home/toasterkief/PyLibrary/Web/Flask/symphonyIO/venv/lib/python3.8/site-packages/flask/app.py", line 1950, in full_dispatch_request
    rv = self.dispatch_request()
  File "/home/toasterkief/PyLibrary/Web/Flask/symphonyIO/venv/lib/python3.8/site-packages/flask/app.py", line 1936, in dispatch_request
    return self.view_functions[rule.endpoint](**req.view_args)
  File "/home/toasterkief/PyLibrary/Web/Flask/symphonyIO/venv/lib/python3.8/site-packages/flask_login/utils.py", line 272, in decorated_view
    return func(*args, **kwargs)
  File "/home/toasterkief/PyLibrary/Web/Flask/symphonyIO/app/routes.py", line 190, in upload
    f.save(os.path.join(app.config['UPLOAD_FOLDER'], filename))
NameError: name 'os' is not defined
2020-04-28 18:05:53,937 INFO: Symphony IO Site Started Up [in /home/toasterkief/PyLibrary/Web/Flask/symphonyIO/app/__init__.py:59]
